<?xml version="1.0" encoding="utf-8"?>
<!-- =================================================================================== -->
<!-- |    This document was autogenerated by xacro from workcell.xacro                 | -->
<!-- |    EDITING THIS FILE BY HAND IS NOT RECOMMENDED                                 | -->
<!-- =================================================================================== -->
<robot name="bf3dp">
  <!-- Conversion were obtained from http://www.e-paint.co.uk/Lab_values.asp
       unless otherwise stated. -->
  <!-- link list -->
  <link name="robot_base_link">
    <inertial>
      <origin xyz="0.0 0.0 0.0"/>
      <mass value="120.00000"/>
      <inertia ixx="-4.98000" ixy="0.00000" ixz="2.70000" iyy="-5.95200" iyz="0.00000" izz="0.82800"/>
    </inertial>
    <visual>
      <geometry>
        <mesh filename="package://abb_irb4600_40_255/meshes/visual/base_link.stl"/>
      </geometry>
      <material name="">
        <color rgba="0.7725490 0.7803922 0.7686275 1"/>
      </material>
    </visual>
    <collision>
      <geometry>
        <mesh filename="package://abb_irb4600_40_255/meshes/collision/base_link.stl"/>
      </geometry>
    </collision>
  </link>
  <link name="robot_link_1">
    <inertial>
      <origin xyz="0.18000 0.00000 0.50000"/>
      <mass value="120.00000"/>
      <inertia ixx="-4.98000" ixy="0.00000" ixz="2.70000" iyy="-5.95200" iyz="0.00000" izz="0.82800"/>
    </inertial>
    <visual>
      <geometry>
        <mesh filename="package://abb_irb4600_40_255/meshes/visual/link_1.stl"/>
      </geometry>
      <material name="">
        <color rgba="0.7725490 0.7803922 0.7686275 1"/>
      </material>
    </visual>
    <collision>
      <geometry>
        <mesh filename="package://abb_irb4600_40_255/meshes/collision/link_1.stl"/>
      </geometry>
    </collision>
  </link>
  <link name="robot_link_2">
    <inertial>
      <origin xyz="0.94000 0.08000 -0.34000"/>
      <mass value="120.00000"/>
      <inertia ixx="-2.96000" ixy="2.25600" ixz="-9.58800" iyy="-18.72601" iyz="-0.81600" izz="-14.95000"/>
    </inertial>
    <visual>
      <geometry>
        <mesh filename="package://abb_irb4600_40_255/meshes/visual/link_2.stl"/>
      </geometry>
      <material name="">
        <color rgba="0.7725490 0.7803922 0.7686275 1"/>
      </material>
    </visual>
    <collision>
      <geometry>
        <mesh filename="package://abb_irb4600_40_255/meshes/collision/link_2.stl"/>
      </geometry>
    </collision>
  </link>
  <link name="robot_link_3">
    <inertial>
      <origin xyz="0.07000 -0.26600 0.08800"/>
      <mass value="120.00000"/>
      <inertia ixx="1.34500" ixy="0.55860" ixz="0.18480" iyy="4.65068" iyz="-0.70224" izz="2.76032"/>
    </inertial>
    <visual>
      <geometry>
        <mesh filename="package://abb_irb4600_40_255/meshes/visual/link_3.stl"/>
      </geometry>
      <material name="">
        <color rgba="0.7725490 0.7803922 0.7686275 1"/>
      </material>
    </visual>
    <collision>
      <geometry>
        <mesh filename="package://abb_irb4600_40_255/meshes/collision/link_3.stl"/>
      </geometry>
    </collision>
  </link>
  <link name="robot_link_4">
    <inertial>
      <origin xyz="0.00000 0.00000 1.00000"/>
      <mass value="40.00000"/>
      <inertia ixx="-8.00000" ixy="0.00000" ixz="0.00000" iyy="-8.00000" iyz="0.00000" izz="0.48200"/>
    </inertial>
    <visual>
      <geometry>
        <mesh filename="package://abb_irb4600_40_255/meshes/visual/link_4.stl"/>
      </geometry>
      <material name="">
        <color rgba="0.7725490 0.7803922 0.7686275 1"/>
      </material>
    </visual>
    <collision>
      <geometry>
        <mesh filename="package://abb_irb4600_40_255/meshes/collision/link_4.stl"/>
      </geometry>
    </collision>
  </link>
  <link name="robot_link_5">
    <inertial>
      <origin xyz="0.14000 0.00000 0.00000"/>
      <mass value="10.00000"/>
      <inertia ixx="0.04000" ixy="0.00000" ixz="0.00000" iyy="-0.00900" iyz="0.00000" izz="-0.00400"/>
    </inertial>
    <visual>
      <geometry>
        <mesh filename="package://abb_irb4600_40_255/meshes/visual/link_5.stl"/>
      </geometry>
      <material name="">
        <color rgba="0.7725490 0.7803922 0.7686275 1"/>
      </material>
    </visual>
    <collision>
      <geometry>
        <mesh filename="package://abb_irb4600_40_255/meshes/collision/link_5.stl"/>
      </geometry>
    </collision>
  </link>
  <link name="robot_link_6">
    <inertial>
      <origin xyz="0.08100 -0.09100 0.33200"/>
      <mass value="5.00000"/>
      <inertia ixx="-0.29652" ixy="-0.03686" ixz="0.09396" iyy="-0.28792" iyz="-0.10556" izz="-0.04621"/>
    </inertial>
    <visual>
      <geometry>
        <mesh filename="package://abb_irb4600_40_255/meshes/visual/link_6.stl"/>
      </geometry>
      <material name="">
        <color rgba="0.1882353 0.1960784 0.2039216 1"/>
      </material>
    </visual>
    <collision>
      <geometry>
        <mesh filename="package://abb_irb4600_40_255/meshes/collision/link_6.stl"/>
      </geometry>
    </collision>
  </link>
  <link name="robot_tool0"/>
  <!-- end of link list -->
  <!-- joint list -->
  <joint name="robot_joint_1" type="revolute">
    <parent link="robot_base_link"/>
    <child link="robot_link_1"/>
    <origin rpy="0 0 0 " xyz="0 0 0"/>
    <axis xyz="0 0 1"/>
    <!-- (-180 to 180) -->
    <limit effort="100000" lower="-3.14159265359" upper="3.14159265359" velocity="2.618"/>
    <dynamics damping="0.2" friction="0"/>
  </joint>
  <joint name="robot_joint_2" type="revolute">
    <parent link="robot_link_1"/>
    <child link="robot_link_2"/>
    <origin rpy="0 0 0 " xyz="0.175 0 0.495"/>
    <axis xyz="0 1 0"/>
    <!-- (-90 to 150) -->
    <limit effort="100000" lower="-1.57079632679" upper="2.61799387799" velocity="2.618"/>
    <dynamics damping="0.2" friction="0"/>
  </joint>
  <joint name="robot_joint_3" type="revolute">
    <parent link="robot_link_2"/>
    <child link="robot_link_3"/>
    <origin rpy="0 0 0 " xyz="0 0 1.095"/>
    <axis xyz="0 1 0"/>
    <!-- (-180 to 75) -->
    <limit effort="100000" lower="-3.14159265359" upper="1.308996939" velocity="2.618"/>
    <dynamics damping="0.2" friction="0"/>
  </joint>
  <joint name="robot_joint_4" type="revolute">
    <parent link="robot_link_3"/>
    <child link="robot_link_4"/>
    <origin rpy="0 0 0 " xyz="0.331 0 0.175"/>
    <axis xyz="1 0 0"/>
    <!-- (-400 to 400) -->
    <limit effort="10000" lower="-6.98131700798" upper="6.98131700798" velocity="6.2832"/>
    <dynamics damping="0.2" friction="0"/>
  </joint>
  <joint name="robot_joint_5" type="revolute">
    <parent link="robot_link_4"/>
    <child link="robot_link_5"/>
    <origin rpy="0 0 0 " xyz="0.939 0 0"/>
    <axis xyz="0 1 0"/>
    <!-- (-125 to 120) -->
    <limit effort="100000" lower="-2.18166" upper="2.18166156499" velocity="6.2832"/>
    <dynamics damping="0.2" friction="0"/>
  </joint>
  <joint name="robot_joint_6" type="revolute">
    <parent link="robot_link_5"/>
    <child link="robot_link_6"/>
    <origin rpy="0 1.57079632679 0" xyz="0.135 0 0"/>
    <axis xyz="0 0 1"/>
    <!-- (-400 to 400) -->
    <limit effort="100000" lower="-6.98131700798" upper="6.98131700798" velocity="7.854"/>
    <dynamics damping="0.2" friction="0"/>
  </joint>
  <joint name="robot_joint_6-tool0" type="fixed">
    <parent link="robot_link_6"/>
    <child link="robot_tool0"/>
    <origin rpy="0 0 0" xyz="0 0 0"/>
  </joint>
  <!-- end of joint list -->
  <!-- ROS base_link to ABB World Coordinates transform >
    <link name="${prefix}base" />
    <joint name="${prefix}base_link-base" type="fixed">
      <origin xyz="0 0 0" rpy="0 0 0"/>
      <parent link="${prefix}base_link"/>
      <child link="${prefix}base"/>
    </joint-->
  <link name="mu100_base_link">
    <visual>
      <mesh filename="package://bf3dp_support/meshes/mu100/visual.stl"/>
    </visual>
    <collision>
      <mesh filename="package://bf3dp_support/meshes/mu100/collision.stl"/>
    </collision>
  </link>
  <link name="mu100_shaft">
    <visual name="shaft_base">
      <origin rpy="0 0 0" xyz="0 0 0"/>
      <geometry>
        <cylinder length="0.01" radius="0.02"/>
      </geometry>
    </visual>
    <visual name="shaft_end">
      <origin rpy="0 0 0" xyz="0 0 0.01"/>
      <geometry>
        <cylinder length="0.03" radius="0.01"/>
      </geometry>
    </visual>
  </link>
  <link name="mu100_tool0"/>
  <joint name="mu100_joint_1" type="continuous">
    <parent link="mu100_base_link"/>
    <child link="mu100_shaft"/>
    <origin rpy="0 0 0" xyz="0 0 0"/>
  </joint>
  <joint name="mu100_joint1_tool0" type="fixed">
    <origin rpy="0 0 0" xyz="0 0 0.01"/>
    <parent link="mu100_shaft"/>
    <child link="mu100_tool0"/>
  </joint>
  <!-- link list -->
  <link name="world"/>
  <joint name="world_robot" type="fixed">
    <origin rpy="0 0 0" xyz="0 0 0"/>
    <parent link="world"/>
    <child link="robot_base_link"/>
  </joint>
  <joint name="world_motor_unit" type="fixed">
    <origin rpy="0 0 0" xyz="0 0.5 0"/>
    <parent link="world"/>
    <child link="mu100_base_link"/>
  </joint>
</robot>
